Traceback (most recent call last):
  File "F:\OneDrive - str.ucture GmbH\General\CoKLIMAx (Phase 2)\coklimax\venv\lib\site-packages\jupyter_cache\executors\utils.py", line 58, in single_nb_execution
    executenb(
  File "F:\OneDrive - str.ucture GmbH\General\CoKLIMAx (Phase 2)\coklimax\venv\lib\site-packages\nbclient\client.py", line 1314, in execute
    return NotebookClient(nb=nb, resources=resources, km=km, **kwargs).execute()
  File "F:\OneDrive - str.ucture GmbH\General\CoKLIMAx (Phase 2)\coklimax\venv\lib\site-packages\jupyter_core\utils\__init__.py", line 165, in wrapped
    return loop.run_until_complete(inner)
  File "C:\Users\Shailesh\AppData\Local\Programs\Python\Python310\lib\asyncio\base_events.py", line 641, in run_until_complete
    return future.result()
  File "F:\OneDrive - str.ucture GmbH\General\CoKLIMAx (Phase 2)\coklimax\venv\lib\site-packages\nbclient\client.py", line 709, in async_execute
    await self.async_execute_cell(
  File "F:\OneDrive - str.ucture GmbH\General\CoKLIMAx (Phase 2)\coklimax\venv\lib\site-packages\nbclient\client.py", line 1062, in async_execute_cell
    await self._check_raise_for_error(cell, cell_index, exec_reply)
  File "F:\OneDrive - str.ucture GmbH\General\CoKLIMAx (Phase 2)\coklimax\venv\lib\site-packages\nbclient\client.py", line 918, in _check_raise_for_error
    raise CellExecutionError.from_cell_and_msg(cell, exec_reply_content)
nbclient.exceptions.CellExecutionError: An error occurred while executing the following cell:
------------------
from sentinelhub import (
    SHConfig,
    DataCollection,
    SentinelHubCatalog,
    SentinelHubRequest,
    SentinelHubStatistical,
    BBox,
    bbox_to_dimensions,
    CRS,
    MimeType,
    Geometry,
    MosaickingOrder,
)

import datetime
import os
import getpass
import matplotlib.pyplot as plt
import numpy as np

from utils import plot_image
------------------


[1;31m---------------------------------------------------------------------------[0m
[1;31mModuleNotFoundError[0m                       Traceback (most recent call last)
Cell [1;32mIn[2], line 21[0m
[0;32m     18[0m [38;5;28;01mimport[39;00m [38;5;21;01mmatplotlib[39;00m[38;5;21;01m.[39;00m[38;5;21;01mpyplot[39;00m [38;5;28;01mas[39;00m [38;5;21;01mplt[39;00m
[0;32m     19[0m [38;5;28;01mimport[39;00m [38;5;21;01mnumpy[39;00m [38;5;28;01mas[39;00m [38;5;21;01mnp[39;00m
[1;32m---> 21[0m [38;5;28;01mfrom[39;00m [38;5;21;01mutils[39;00m [38;5;28;01mimport[39;00m plot_image

[1;31mModuleNotFoundError[0m: No module named 'utils'

